2025-08-08 08:44:14 [INFO] Iniciando monitor de archivos...
2025-08-08 08:44:14 [INFO] Detectado archivo: ASIGNACION_TANGIBLES_RV_20250807.csv
2025-08-08 08:44:15 [INFO] 11583 registros insertados en tabla 'alarma_asignacion_tangibles' desde archivo: ASIGNACION_TANGIBLES_RV_20250807.csv
2025-08-08 08:44:15 [INFO] Procedimiento ejecutado: sp_update_resumen_simcard2 con parámetro: N/A
2025-08-08 08:44:15 [INFO] Archivo procesado correctamente: ASIGNACION_TANGIBLES_RV_20250807.csv
2025-08-08 08:44:55 [INFO] Detectado archivo: ASIGNACION_TANGIBLES_RV_20250807.csv
2025-08-08 08:44:55 [INFO] 11583 registros insertados en tabla 'alarma_asignacion_tangibles' desde archivo: ASIGNACION_TANGIBLES_RV_20250807.csv
2025-08-08 08:44:55 [INFO] Procedimiento ejecutado: sp_update_resumen_simcard2 con parámetro: N/A
2025-08-08 08:44:55 [INFO] Archivo procesado correctamente: ASIGNACION_TANGIBLES_RV_20250807.csv
2025-08-08 08:45:16 [INFO] Iniciando monitor de archivos...
2025-08-08 08:45:16 [INFO] Detectado archivo: ASIGNACION_TANGIBLES_RV_20250807.csv
2025-08-08 08:45:16 [INFO] 11583 registros insertados en tabla 'alarma_asignacion_tangibles' desde archivo: ASIGNACION_TANGIBLES_RV_20250807.csv
2025-08-08 08:45:16 [INFO] Procedimiento ejecutado: sp_update_resumen_simcard2 con parámetro: N/A
2025-08-08 08:45:16 [INFO] Archivo procesado correctamente: ASIGNACION_TANGIBLES_RV_20250807.csv
2025-08-08 08:48:05 [INFO] Iniciando monitor de archivos...
2025-08-08 08:48:10 [INFO] Detectado archivo: ASIGNACION_TANGIBLES_RV_20250807.csv
2025-08-08 08:48:11 [INFO] 11583 registros insertados en tabla 'alarma_asignacion_tangibles' desde archivo: ASIGNACION_TANGIBLES_RV_20250807.csv
2025-08-08 08:48:11 [INFO] Procedimiento ejecutado: sp_update_resumen_simcard2 con parámetro: N/A
2025-08-08 08:48:11 [INFO] Archivo procesado correctamente: ASIGNACION_TANGIBLES_RV_20250807.csv
2025-08-08 08:49:24 [INFO] Iniciando monitor de archivos...
2025-08-08 08:49:29 [INFO] Detectado archivo: ASIGNACION_TANGIBLES_RV_20250807.csv
2025-08-08 08:49:31 [INFO] 11583 registros insertados en tabla 'alarma_asignacion_tangibles' desde archivo: ASIGNACION_TANGIBLES_RV_20250807.csv
2025-08-08 08:49:31 [INFO] Procedimiento ejecutado: sp_update_resumen_simcard2 con parámetro: N/A
2025-08-08 08:49:31 [INFO] Archivo procesado correctamente: ASIGNACION_TANGIBLES_RV_20250807.csv
2025-08-08 08:53:24 [INFO] Iniciando monitor de archivos...
2025-08-08 08:53:24 [INFO] Detectado archivo: ASIGNACION_TANGIBLES_RV_20250807.csv
2025-08-08 08:53:24 [INFO] 11583 registros insertados en tabla 'alarma_asignacion_tangibles' desde archivo: ASIGNACION_TANGIBLES_RV_20250807.csv
2025-08-08 08:53:24 [INFO] Procedimiento ejecutado: sp_update_resumen_simcard2 con parámetro: N/A
2025-08-08 08:53:24 [INFO] Archivo procesado correctamente: ASIGNACION_TANGIBLES_RV_20250807.csv
2025-08-08 08:55:25 [INFO] Iniciando monitor de archivos...
2025-08-08 08:55:25 [INFO] Detectado archivo: ASIGNACION_TANGIBLES_RV_20250807.csv
2025-08-08 08:55:26 [INFO] 11583 registros insertados en tabla 'alarma_asignacion_tangibles' desde archivo: ASIGNACION_TANGIBLES_RV_20250807.csv
2025-08-08 08:55:26 [INFO] Procedimiento ejecutado: sp_update_resumen_simcard2 con parámetro: N/A
2025-08-08 08:55:26 [INFO] Archivo procesado correctamente: ASIGNACION_TANGIBLES_RV_20250807.csv
2025-08-08 08:56:05 [INFO] Iniciando monitor de archivos...
2025-08-08 08:56:10 [INFO] Detectado archivo: ASIGNACION_TANGIBLES_RV_20250807.csv
2025-08-08 08:56:12 [INFO] 11583 registros insertados en tabla 'alarma_asignacion_tangibles' desde archivo: ASIGNACION_TANGIBLES_RV_20250807.csv
2025-08-08 08:56:12 [INFO] Procedimiento ejecutado: sp_update_resumen_simcard2 con parámetro: N/A
2025-08-08 08:56:12 [INFO] Archivo procesado correctamente: ASIGNACION_TANGIBLES_RV_20250807.csv
2025-08-08 08:57:55 [INFO] Iniciando monitor de archivos...
2025-08-08 08:58:00 [INFO] Detectado archivo: ASIGNACION_TANGIBLES_RV_20250807.csv
2025-08-08 08:58:03 [ERROR] Failed executing the operation; Not enough parameters for the SQL statement
Traceback (most recent call last):
  File "C:\workspace\rv\projects\AutoUploader\db.py", line 33, in insert_into_table
    cursor.executemany(sql, batch)
    ~~~~~~~~~~~~~~~~~~^^^^^^^^^^^^
  File "C:\Users\wilme\AppData\Local\Programs\Python\Python313\Lib\site-packages\mysql\connector\cursor_cext.py", line 478, in executemany
    stmt = self._batch_insert(operation, seq_params)
  File "C:\Users\wilme\AppData\Local\Programs\Python\Python313\Lib\site-packages\mysql\connector\cursor_cext.py", line 432, in _batch_insert
    raise InterfaceError(f"Failed executing the operation; {err}") from None
mysql.connector.errors.InterfaceError: Failed executing the operation; Not enough parameters for the SQL statement
2025-08-08 08:58:03 [ERROR] Error procesando archivo ASIGNACION_TANGIBLES_RV_20250807.csv: Failed executing the operation; Not enough parameters for the SQL statement
2025-08-08 08:58:03 [ERROR] Failed executing the operation; Not enough parameters for the SQL statement
Traceback (most recent call last):
  File "C:\workspace\rv\projects\AutoUploader\processor.py", line 171, in procesar_archivo
    insert_into_table(tabla, todas_las_columnas, filas_finales, batch_size=MAX_BATCH_SIZE, insert_type=tipo_insercion)
    ~~~~~~~~~~~~~~~~~^^^^^^^^^^^^^^^^^^^^^^^^^^^^^^^^^^^^^^^^^^^^^^^^^^^^^^^^^^^^^^^^^^^^^^^^^^^^^^^^^^^^^^^^^^^^^^^^^
  File "C:\workspace\rv\projects\AutoUploader\db.py", line 38, in insert_into_table
    raise e
  File "C:\workspace\rv\projects\AutoUploader\db.py", line 33, in insert_into_table
    cursor.executemany(sql, batch)
    ~~~~~~~~~~~~~~~~~~^^^^^^^^^^^^
  File "C:\Users\wilme\AppData\Local\Programs\Python\Python313\Lib\site-packages\mysql\connector\cursor_cext.py", line 478, in executemany
    stmt = self._batch_insert(operation, seq_params)
  File "C:\Users\wilme\AppData\Local\Programs\Python\Python313\Lib\site-packages\mysql\connector\cursor_cext.py", line 432, in _batch_insert
    raise InterfaceError(f"Failed executing the operation; {err}") from None
mysql.connector.errors.InterfaceError: Failed executing the operation; Not enough parameters for the SQL statement
2025-08-08 08:58:03 [ERROR] Archivo movido a carpeta de errores: ASIGNACION_TANGIBLES_RV_20250807.csv
2025-08-08 08:59:39 [INFO] Iniciando monitor de archivos...
2025-08-08 08:59:39 [INFO] Detectado archivo: ASIGNACION_TANGIBLES_RV_20250807.csv
2025-08-08 08:59:40 [ERROR] Failed executing the operation; Not enough parameters for the SQL statement
Traceback (most recent call last):
  File "C:\workspace\rv\projects\AutoUploader\db.py", line 33, in insert_into_table
    cursor.executemany(sql, batch)
    ~~~~~~~~~~~~~~~~~~^^^^^^^^^^^^
  File "C:\Users\wilme\AppData\Local\Programs\Python\Python313\Lib\site-packages\mysql\connector\cursor_cext.py", line 478, in executemany
    stmt = self._batch_insert(operation, seq_params)
  File "C:\Users\wilme\AppData\Local\Programs\Python\Python313\Lib\site-packages\mysql\connector\cursor_cext.py", line 432, in _batch_insert
    raise InterfaceError(f"Failed executing the operation; {err}") from None
mysql.connector.errors.InterfaceError: Failed executing the operation; Not enough parameters for the SQL statement
2025-08-08 08:59:40 [ERROR] Error procesando archivo ASIGNACION_TANGIBLES_RV_20250807.csv: Failed executing the operation; Not enough parameters for the SQL statement
2025-08-08 08:59:40 [ERROR] Failed executing the operation; Not enough parameters for the SQL statement
Traceback (most recent call last):
  File "C:\workspace\rv\projects\AutoUploader\processor.py", line 167, in procesar_archivo
    insert_into_table(tabla, todas_las_columnas, filas_finales, batch_size=MAX_BATCH_SIZE, insert_type=tipo_insercion)
    ~~~~~~~~~~~~~~~~~^^^^^^^^^^^^^^^^^^^^^^^^^^^^^^^^^^^^^^^^^^^^^^^^^^^^^^^^^^^^^^^^^^^^^^^^^^^^^^^^^^^^^^^^^^^^^^^^^
  File "C:\workspace\rv\projects\AutoUploader\db.py", line 38, in insert_into_table
    raise e
  File "C:\workspace\rv\projects\AutoUploader\db.py", line 33, in insert_into_table
    cursor.executemany(sql, batch)
    ~~~~~~~~~~~~~~~~~~^^^^^^^^^^^^
  File "C:\Users\wilme\AppData\Local\Programs\Python\Python313\Lib\site-packages\mysql\connector\cursor_cext.py", line 478, in executemany
    stmt = self._batch_insert(operation, seq_params)
  File "C:\Users\wilme\AppData\Local\Programs\Python\Python313\Lib\site-packages\mysql\connector\cursor_cext.py", line 432, in _batch_insert
    raise InterfaceError(f"Failed executing the operation; {err}") from None
mysql.connector.errors.InterfaceError: Failed executing the operation; Not enough parameters for the SQL statement
2025-08-08 08:59:40 [ERROR] Archivo movido a carpeta de errores: ASIGNACION_TANGIBLES_RV_20250807.csv
2025-08-08 09:00:23 [INFO] Iniciando monitor de archivos...
2025-08-08 09:00:23 [INFO] Detectado archivo: ASIGNACION_TANGIBLES_RV_20250807.csv
2025-08-08 09:00:24 [ERROR] Failed executing the operation; Not enough parameters for the SQL statement
Traceback (most recent call last):
  File "C:\workspace\rv\projects\AutoUploader\db.py", line 34, in insert_into_table
    cursor.executemany(sql, batch)
    ~~~~~~~~~~~~~~~~~~^^^^^^^^^^^^
  File "C:\Users\wilme\AppData\Local\Programs\Python\Python313\Lib\site-packages\mysql\connector\cursor_cext.py", line 478, in executemany
    stmt = self._batch_insert(operation, seq_params)
  File "C:\Users\wilme\AppData\Local\Programs\Python\Python313\Lib\site-packages\mysql\connector\cursor_cext.py", line 432, in _batch_insert
    raise InterfaceError(f"Failed executing the operation; {err}") from None
mysql.connector.errors.InterfaceError: Failed executing the operation; Not enough parameters for the SQL statement
2025-08-08 09:00:24 [ERROR] Error procesando archivo ASIGNACION_TANGIBLES_RV_20250807.csv: Failed executing the operation; Not enough parameters for the SQL statement
2025-08-08 09:00:24 [ERROR] Failed executing the operation; Not enough parameters for the SQL statement
Traceback (most recent call last):
  File "C:\workspace\rv\projects\AutoUploader\processor.py", line 167, in procesar_archivo
    insert_into_table(tabla, todas_las_columnas, filas_finales, batch_size=MAX_BATCH_SIZE, insert_type=tipo_insercion)
    ~~~~~~~~~~~~~~~~~^^^^^^^^^^^^^^^^^^^^^^^^^^^^^^^^^^^^^^^^^^^^^^^^^^^^^^^^^^^^^^^^^^^^^^^^^^^^^^^^^^^^^^^^^^^^^^^^^
  File "C:\workspace\rv\projects\AutoUploader\db.py", line 39, in insert_into_table
    raise e
  File "C:\workspace\rv\projects\AutoUploader\db.py", line 34, in insert_into_table
    cursor.executemany(sql, batch)
    ~~~~~~~~~~~~~~~~~~^^^^^^^^^^^^
  File "C:\Users\wilme\AppData\Local\Programs\Python\Python313\Lib\site-packages\mysql\connector\cursor_cext.py", line 478, in executemany
    stmt = self._batch_insert(operation, seq_params)
  File "C:\Users\wilme\AppData\Local\Programs\Python\Python313\Lib\site-packages\mysql\connector\cursor_cext.py", line 432, in _batch_insert
    raise InterfaceError(f"Failed executing the operation; {err}") from None
mysql.connector.errors.InterfaceError: Failed executing the operation; Not enough parameters for the SQL statement
2025-08-08 09:00:24 [ERROR] Archivo movido a carpeta de errores: ASIGNACION_TANGIBLES_RV_20250807.csv
2025-08-08 09:08:08 [INFO] Iniciando monitor de archivos...
2025-08-08 09:08:13 [INFO] Detectado archivo: ASIGNACION_TANGIBLES_RV_20250807.csv
2025-08-08 09:08:15 [INFO] 11583 registros insertados en tabla 'alarma_asignacion_tangibles' desde archivo: ASIGNACION_TANGIBLES_RV_20250807.csv
2025-08-08 09:08:15 [INFO] Procedimiento ejecutado: sp_update_resumen_simcard2 con parámetro: N/A
2025-08-08 09:08:15 [INFO] Archivo procesado correctamente: ASIGNACION_TANGIBLES_RV_20250807.csv
2025-08-08 09:11:27 [INFO] Iniciando monitor de archivos...
2025-08-08 09:11:32 [INFO] Detectado archivo: ASIGNACION_TANGIBLES_RV_20250807.csv
2025-08-08 09:11:34 [INFO] 11583 registros insertados en tabla 'alarma_asignacion_tangibles' desde archivo: ASIGNACION_TANGIBLES_RV_20250807.csv
2025-08-08 09:11:34 [INFO] Procedimiento ejecutado: sp_update_resumen_simcard2 con parámetro: N/A
2025-08-08 09:11:34 [INFO] Archivo procesado correctamente: ASIGNACION_TANGIBLES_RV_20250807.csv
2025-08-08 09:12:50 [INFO] Iniciando monitor de archivos...
2025-08-08 09:12:55 [INFO] Detectado archivo: ASIGNACION_TANGIBLES_RV_20250807.csv
2025-08-08 09:12:57 [INFO] 11583 registros insertados en tabla 'alarma_asignacion_tangibles' desde archivo: ASIGNACION_TANGIBLES_RV_20250807.csv
2025-08-08 09:12:57 [INFO] Procedimiento ejecutado: sp_update_resumen_simcard2 con parámetro: N/A
2025-08-08 09:12:57 [INFO] Archivo procesado correctamente: ASIGNACION_TANGIBLES_RV_20250807.csv
2025-08-08 09:14:43 [INFO] Iniciando monitor de archivos...
2025-08-08 09:14:48 [INFO] Detectado archivo: ASIGNACION_TANGIBLES_RV_20250807.csv
2025-08-08 09:14:49 [INFO] 11583 registros insertados en tabla 'alarma_asignacion_tangibles' desde archivo: ASIGNACION_TANGIBLES_RV_20250807.csv
2025-08-08 09:14:49 [INFO] Procedimiento ejecutado: sp_update_resumen_simcard2 con parámetro: N/A
2025-08-08 09:14:49 [INFO] Archivo procesado correctamente: ASIGNACION_TANGIBLES_RV_20250807.csv
2025-08-08 09:21:54 [INFO] Iniciando monitor de archivos...
2025-08-08 09:21:59 [INFO] Detectado archivo: ASIGNACION_TANGIBLES_RV_20250807.csv
2025-08-08 09:22:00 [INFO] 11583 registros insertados en tabla 'alarma_asignacion_tangibles' desde archivo: ASIGNACION_TANGIBLES_RV_20250807.csv
2025-08-08 09:22:00 [INFO] Procedimiento ejecutado: sp_update_resumen_simcard2 con parámetro: N/A
2025-08-08 09:22:00 [INFO] Archivo procesado correctamente: ASIGNACION_TANGIBLES_RV_20250807.csv
2025-08-08 09:22:58 [INFO] Iniciando monitor de archivos...
2025-08-08 09:23:03 [INFO] Detectado archivo: ASIGNACION_TANGIBLES_RV_20250807.csv
2025-08-08 09:23:04 [ERROR] 1292 (22007): Incorrect date value: '06/AUG/2025' for column 'FECHA_PDV' at row 1
Traceback (most recent call last):
  File "C:\Users\wilme\AppData\Local\Programs\Python\Python313\Lib\site-packages\mysql\connector\connection_cext.py", line 706, in cmd_query
    self._cmysql.query(
    ~~~~~~~~~~~~~~~~~~^
        query,
        ^^^^^^
    ...<3 lines>...
        query_attrs=self.query_attrs,
        ^^^^^^^^^^^^^^^^^^^^^^^^^^^^^
    )
    ^
_mysql_connector.MySQLInterfaceError: Incorrect date value: '06/AUG/2025' for column 'FECHA_PDV' at row 1

The above exception was the direct cause of the following exception:

Traceback (most recent call last):
  File "C:\workspace\rv\projects\AutoUploader\db.py", line 34, in insert_into_table
    cursor.executemany(sql, batch)
    ~~~~~~~~~~~~~~~~~~^^^^^^^^^^^^
  File "C:\Users\wilme\AppData\Local\Programs\Python\Python313\Lib\site-packages\mysql\connector\cursor_cext.py", line 491, in executemany
    self.execute(operation, params)
    ~~~~~~~~~~~~^^^^^^^^^^^^^^^^^^^
  File "C:\Users\wilme\AppData\Local\Programs\Python\Python313\Lib\site-packages\mysql\connector\cursor_cext.py", line 357, in execute
    result = self._connection.cmd_query(
        stmt,
    ...<2 lines>...
        raw_as_string=self._raw_as_string,
    )
  File "C:\Users\wilme\AppData\Local\Programs\Python\Python313\Lib\site-packages\mysql\connector\opentelemetry\context_propagation.py", line 97, in wrapper
    return method(cnx, *args, **kwargs)
  File "C:\Users\wilme\AppData\Local\Programs\Python\Python313\Lib\site-packages\mysql\connector\connection_cext.py", line 714, in cmd_query
    raise get_mysql_exception(
        err.errno, msg=err.msg, sqlstate=err.sqlstate
    ) from err
mysql.connector.errors.DataError: 1292 (22007): Incorrect date value: '06/AUG/2025' for column 'FECHA_PDV' at row 1
2025-08-08 09:23:04 [ERROR] Error procesando archivo ASIGNACION_TANGIBLES_RV_20250807.csv: 1292 (22007): Incorrect date value: '06/AUG/2025' for column 'FECHA_PDV' at row 1
2025-08-08 09:23:04 [ERROR] 1292 (22007): Incorrect date value: '06/AUG/2025' for column 'FECHA_PDV' at row 1
Traceback (most recent call last):
  File "C:\Users\wilme\AppData\Local\Programs\Python\Python313\Lib\site-packages\mysql\connector\connection_cext.py", line 706, in cmd_query
    self._cmysql.query(
    ~~~~~~~~~~~~~~~~~~^
        query,
        ^^^^^^
    ...<3 lines>...
        query_attrs=self.query_attrs,
        ^^^^^^^^^^^^^^^^^^^^^^^^^^^^^
    )
    ^
_mysql_connector.MySQLInterfaceError: Incorrect date value: '06/AUG/2025' for column 'FECHA_PDV' at row 1

The above exception was the direct cause of the following exception:

Traceback (most recent call last):
  File "C:\workspace\rv\projects\AutoUploader\processor.py", line 169, in procesar_archivo
    insert_into_table(tabla, columnas_finales, filas_finales, batch_size=MAX_BATCH_SIZE, insert_type=tipo_insercion)
    ~~~~~~~~~~~~~~~~~^^^^^^^^^^^^^^^^^^^^^^^^^^^^^^^^^^^^^^^^^^^^^^^^^^^^^^^^^^^^^^^^^^^^^^^^^^^^^^^^^^^^^^^^^^^^^^^
  File "C:\workspace\rv\projects\AutoUploader\db.py", line 39, in insert_into_table
    raise e
  File "C:\workspace\rv\projects\AutoUploader\db.py", line 34, in insert_into_table
    cursor.executemany(sql, batch)
    ~~~~~~~~~~~~~~~~~~^^^^^^^^^^^^
  File "C:\Users\wilme\AppData\Local\Programs\Python\Python313\Lib\site-packages\mysql\connector\cursor_cext.py", line 491, in executemany
    self.execute(operation, params)
    ~~~~~~~~~~~~^^^^^^^^^^^^^^^^^^^
  File "C:\Users\wilme\AppData\Local\Programs\Python\Python313\Lib\site-packages\mysql\connector\cursor_cext.py", line 357, in execute
    result = self._connection.cmd_query(
        stmt,
    ...<2 lines>...
        raw_as_string=self._raw_as_string,
    )
  File "C:\Users\wilme\AppData\Local\Programs\Python\Python313\Lib\site-packages\mysql\connector\opentelemetry\context_propagation.py", line 97, in wrapper
    return method(cnx, *args, **kwargs)
  File "C:\Users\wilme\AppData\Local\Programs\Python\Python313\Lib\site-packages\mysql\connector\connection_cext.py", line 714, in cmd_query
    raise get_mysql_exception(
        err.errno, msg=err.msg, sqlstate=err.sqlstate
    ) from err
mysql.connector.errors.DataError: 1292 (22007): Incorrect date value: '06/AUG/2025' for column 'FECHA_PDV' at row 1
2025-08-08 09:23:04 [ERROR] Archivo movido a carpeta de errores: ASIGNACION_TANGIBLES_RV_20250807.csv
2025-08-08 10:01:16 [INFO] Iniciando monitor de archivos...
2025-08-08 10:01:21 [INFO] Detectado archivo: ASIGNACION_TANGIBLES_RV_20250807.csv
2025-08-08 10:01:21 [INFO] Orden de columnas calculadas: ['FECHA_PDV', 'Periodo']
2025-08-08 10:01:28 [INFO] 11583 registros insertados en tabla 'alarma_asignacion_tangibles' desde archivo: ASIGNACION_TANGIBLES_RV_20250807.csv
2025-08-08 10:01:28 [INFO] Procedimiento ejecutado: sp_update_resumen_simcard2 con parámetro: N/A
2025-08-08 10:01:28 [INFO] Archivo procesado correctamente: ASIGNACION_TANGIBLES_RV_20250807.csv
2025-08-08 10:04:23 [INFO] Detectado archivo: KPI_DEALER_RV_20250807.csv
2025-08-08 10:04:23 [INFO] Orden de columnas calculadas: ['FECHA_ACTUALIZADO']
2025-08-08 10:04:23 [INFO] 145 registros insertados en tabla 'kpisdealer' desde archivo: KPI_DEALER_RV_20250807.csv
2025-08-08 10:04:23 [INFO] Archivo procesado correctamente: KPI_DEALER_RV_20250807.csv
2025-08-08 10:08:42 [INFO] Iniciando monitor de archivos...
2025-08-08 10:08:47 [INFO] Detectado archivo: KPI_DEALER_RV_20250807.csv
2025-08-08 10:08:47 [INFO] Orden de columnas calculadas: ['FECHA_ACTUALIZADO']
2025-08-08 10:08:48 [INFO] 145 registros insertados en tabla 'kpisdealer' desde archivo: KPI_DEALER_RV_20250807.csv
2025-08-08 10:08:48 [INFO] Archivo procesado correctamente: KPI_DEALER_RV_20250807.csv
2025-08-08 10:10:39 [INFO] Iniciando monitor de archivos...
2025-08-08 10:10:54 [INFO] Detectado archivo: KPI_DEALER_RV_20250807.csv
2025-08-08 10:10:54 [INFO] Orden de columnas calculadas: ['FECHA_ACTUALIZADO']
2025-08-08 10:10:54 [INFO] 145 registros insertados en tabla 'kpisdealer' desde archivo: KPI_DEALER_RV_20250807.csv
2025-08-08 10:10:54 [INFO] Archivo procesado correctamente: KPI_DEALER_RV_20250807.csv
2025-08-08 10:11:45 [INFO] Iniciando monitor de archivos...
2025-08-08 10:11:50 [INFO] Detectado archivo: KPI_DEALER_RV_20250807.csv
2025-08-08 10:11:50 [INFO] Orden de columnas calculadas: ['FECHA_ACTUALIZADO']
2025-08-08 10:11:50 [INFO] 145 registros insertados en tabla 'kpisdealer' desde archivo: KPI_DEALER_RV_20250807.csv
2025-08-08 10:11:50 [INFO] Archivo procesado correctamente: KPI_DEALER_RV_20250807.csv
2025-08-08 10:18:06 [INFO] Iniciando monitor de archivos...
2025-08-08 10:18:26 [INFO] Detectado archivo: KPI_DEALER_RV_20250807.csv
2025-08-08 10:18:26 [INFO] Orden de columnas calculadas: ['FECHA_ACTUALIZADO']
2025-08-08 10:18:26 [INFO] 145 registros insertados en tabla 'kpisdealer' desde archivo: KPI_DEALER_RV_20250807.csv
2025-08-08 10:18:26 [INFO] Archivo procesado correctamente: KPI_DEALER_RV_20250807.csv
2025-08-08 10:20:15 [INFO] Iniciando monitor de archivos...
2025-08-08 10:20:25 [INFO] Detectado archivo: KPI_DEALER_RV_20250807.csv
2025-08-08 10:20:25 [INFO] Orden de columnas calculadas: ['FECHA_ACTUALIZADO']
2025-08-08 10:20:25 [INFO] 145 registros insertados en tabla 'kpisdealer' desde archivo: KPI_DEALER_RV_20250807.csv
2025-08-08 10:20:25 [INFO] Archivo procesado correctamente: KPI_DEALER_RV_20250807.csv
2025-08-08 10:24:40 [INFO] Iniciando monitor de archivos...
2025-08-08 10:24:45 [INFO] Detectado archivo: KPI_DEALER_RV_20250807.csv
2025-08-08 10:24:45 [INFO] Orden de columnas calculadas: ['FECHA_ACTUALIZADO']
2025-08-08 10:24:45 [INFO] 145 registros insertados en tabla 'kpisdealer' desde archivo: KPI_DEALER_RV_20250807.csv
2025-08-08 10:24:45 [INFO] Archivo procesado correctamente: KPI_DEALER_RV_20250807.csv
2025-08-08 10:41:27 [INFO] Iniciando monitor de archivos...
2025-08-08 10:41:32 [INFO] Detectado archivo: KPI_DEALER_RV_20250807.csv
2025-08-08 10:41:32 [INFO] Orden de columnas calculadas: ['FECHA_ACTUALIZADO']
2025-08-08 10:41:32 [ERROR] 1054 (42S22): Unknown column 'DISTRIBUIDOR' in 'field list'
Traceback (most recent call last):
  File "C:\Users\wilme\AppData\Local\Programs\Python\Python313\Lib\site-packages\mysql\connector\connection_cext.py", line 706, in cmd_query
    self._cmysql.query(
    ~~~~~~~~~~~~~~~~~~^
        query,
        ^^^^^^
    ...<3 lines>...
        query_attrs=self.query_attrs,
        ^^^^^^^^^^^^^^^^^^^^^^^^^^^^^
    )
    ^
_mysql_connector.MySQLInterfaceError: Unknown column 'DISTRIBUIDOR' in 'field list'

The above exception was the direct cause of the following exception:

Traceback (most recent call last):
  File "C:\workspace\rv\projects\AutoUploader\db.py", line 33, in insert_into_table
    cursor.executemany(sql, batch)
    ~~~~~~~~~~~~~~~~~~^^^^^^^^^^^^
  File "C:\Users\wilme\AppData\Local\Programs\Python\Python313\Lib\site-packages\mysql\connector\cursor_cext.py", line 491, in executemany
    self.execute(operation, params)
    ~~~~~~~~~~~~^^^^^^^^^^^^^^^^^^^
  File "C:\Users\wilme\AppData\Local\Programs\Python\Python313\Lib\site-packages\mysql\connector\cursor_cext.py", line 357, in execute
    result = self._connection.cmd_query(
        stmt,
    ...<2 lines>...
        raw_as_string=self._raw_as_string,
    )
  File "C:\Users\wilme\AppData\Local\Programs\Python\Python313\Lib\site-packages\mysql\connector\opentelemetry\context_propagation.py", line 97, in wrapper
    return method(cnx, *args, **kwargs)
  File "C:\Users\wilme\AppData\Local\Programs\Python\Python313\Lib\site-packages\mysql\connector\connection_cext.py", line 714, in cmd_query
    raise get_mysql_exception(
        err.errno, msg=err.msg, sqlstate=err.sqlstate
    ) from err
mysql.connector.errors.ProgrammingError: 1054 (42S22): Unknown column 'DISTRIBUIDOR' in 'field list'
2025-08-08 10:41:32 [ERROR] Error procesando archivo KPI_DEALER_RV_20250807.csv: 1054 (42S22): Unknown column 'DISTRIBUIDOR' in 'field list'
2025-08-08 10:41:32 [ERROR] 1054 (42S22): Unknown column 'DISTRIBUIDOR' in 'field list'
Traceback (most recent call last):
  File "C:\Users\wilme\AppData\Local\Programs\Python\Python313\Lib\site-packages\mysql\connector\connection_cext.py", line 706, in cmd_query
    self._cmysql.query(
    ~~~~~~~~~~~~~~~~~~^
        query,
        ^^^^^^
    ...<3 lines>...
        query_attrs=self.query_attrs,
        ^^^^^^^^^^^^^^^^^^^^^^^^^^^^^
    )
    ^
_mysql_connector.MySQLInterfaceError: Unknown column 'DISTRIBUIDOR' in 'field list'

The above exception was the direct cause of the following exception:

Traceback (most recent call last):
  File "C:\workspace\rv\projects\AutoUploader\processor.py", line 169, in procesar_archivo
    insert_into_table(tabla, columnas_finales, filas_finales, batch_size=MAX_BATCH_SIZE, insert_type=tipo_insercion)
    ~~~~~~~~~~~~~~~~~^^^^^^^^^^^^^^^^^^^^^^^^^^^^^^^^^^^^^^^^^^^^^^^^^^^^^^^^^^^^^^^^^^^^^^^^^^^^^^^^^^^^^^^^^^^^^^^
  File "C:\workspace\rv\projects\AutoUploader\db.py", line 38, in insert_into_table
    raise e
  File "C:\workspace\rv\projects\AutoUploader\db.py", line 33, in insert_into_table
    cursor.executemany(sql, batch)
    ~~~~~~~~~~~~~~~~~~^^^^^^^^^^^^
  File "C:\Users\wilme\AppData\Local\Programs\Python\Python313\Lib\site-packages\mysql\connector\cursor_cext.py", line 491, in executemany
    self.execute(operation, params)
    ~~~~~~~~~~~~^^^^^^^^^^^^^^^^^^^
  File "C:\Users\wilme\AppData\Local\Programs\Python\Python313\Lib\site-packages\mysql\connector\cursor_cext.py", line 357, in execute
    result = self._connection.cmd_query(
        stmt,
    ...<2 lines>...
        raw_as_string=self._raw_as_string,
    )
  File "C:\Users\wilme\AppData\Local\Programs\Python\Python313\Lib\site-packages\mysql\connector\opentelemetry\context_propagation.py", line 97, in wrapper
    return method(cnx, *args, **kwargs)
  File "C:\Users\wilme\AppData\Local\Programs\Python\Python313\Lib\site-packages\mysql\connector\connection_cext.py", line 714, in cmd_query
    raise get_mysql_exception(
        err.errno, msg=err.msg, sqlstate=err.sqlstate
    ) from err
mysql.connector.errors.ProgrammingError: 1054 (42S22): Unknown column 'DISTRIBUIDOR' in 'field list'
2025-08-08 10:41:32 [ERROR] Archivo movido a carpeta de errores: KPI_DEALER_RV_20250807.csv
2025-08-08 10:42:47 [INFO] Iniciando monitor de archivos...
2025-08-08 10:42:52 [INFO] Detectado archivo: KPI_DEALER_RV_20250807.csv
2025-08-08 10:42:52 [INFO] Orden de columnas calculadas: ['FECHA_ACTUALIZADO']
2025-08-08 10:42:52 [INFO] 145 registros insertados en tabla 'kpisdealer' desde archivo: KPI_DEALER_RV_20250807.csv
2025-08-08 10:42:52 [INFO] Archivo procesado correctamente: KPI_DEALER_RV_20250807.csv
2025-08-08 10:44:56 [INFO] Iniciando monitor de archivos...
2025-08-08 10:45:01 [INFO] Detectado archivo: KPI_DEALER_RV_20250807.csv
2025-08-08 10:45:01 [INFO] Orden de columnas calculadas: ['FECHA_ACTUALIZADO']
2025-08-08 10:45:01 [INFO] 145 registros insertados en tabla 'kpisdealer' desde archivo: KPI_DEALER_RV_20250807.csv
2025-08-08 10:45:01 [INFO] Archivo procesado correctamente: KPI_DEALER_RV_20250807.csv
2025-08-08 10:49:02 [INFO] Iniciando monitor de archivos...
2025-08-08 10:49:07 [INFO] Detectado archivo: KPI_DEALER_RV_20250807.csv
2025-08-08 10:49:07 [INFO] Orden de columnas calculadas: ['FECHA_ACTUALIZADO']
2025-08-08 10:49:08 [INFO] 145 registros insertados en tabla 'kpisdealer' desde archivo: KPI_DEALER_RV_20250807.csv
2025-08-08 10:49:08 [INFO] Archivo procesado correctamente: KPI_DEALER_RV_20250807.csv
2025-08-08 10:49:38 [INFO] Detectado archivo: KPI_DEALER_RV_20250807.csv
2025-08-08 10:49:38 [INFO] Orden de columnas calculadas: ['FECHA_ACTUALIZADO']
2025-08-08 10:49:38 [INFO] 145 registros insertados en tabla 'kpisdealer' desde archivo: KPI_DEALER_RV_20250807.csv
2025-08-08 10:49:38 [INFO] Archivo procesado correctamente: KPI_DEALER_RV_20250807.csv
2025-08-08 10:50:43 [INFO] Detectado archivo: ASIGNACION_TANGIBLES_RV_20250808.csv
2025-08-08 10:50:43 [INFO] Orden de columnas calculadas: ['FECHA_PDV', 'Periodo']
2025-08-08 10:50:44 [INFO] 14030 registros insertados en tabla 'alarma_asignacion_tangibles' desde archivo: ASIGNACION_TANGIBLES_RV_20250808.csv
2025-08-08 10:50:44 [INFO] Procedimiento ejecutado: sp_update_resumen_simcard2 con parámetro: N/A
2025-08-08 10:50:44 [INFO] Archivo procesado correctamente: ASIGNACION_TANGIBLES_RV_20250808.csv
2025-08-08 11:01:41 [INFO] Iniciando monitor de archivos...
2025-08-08 11:02:06 [INFO] Detectado archivo: ASIGNACION_TANGIBLES_RV_20250808.csv
2025-08-08 11:02:06 [INFO] Orden de columnas calculadas: ['FECHA_PDV', 'Periodo']
2025-08-08 11:02:08 [INFO] 14030 registros insertados en tabla 'alarma_asignacion_tangibles' desde archivo: ASIGNACION_TANGIBLES_RV_20250808.csv
2025-08-08 11:02:08 [INFO] Procedimiento ejecutado: sp_update_resumen_simcard2 con parámetro: N/A
2025-08-08 11:02:08 [INFO] Archivo procesado correctamente: ASIGNACION_TANGIBLES_RV_20250808.csv
2025-08-08 11:03:37 [INFO] Iniciando monitor de archivos...
2025-08-08 11:03:47 [INFO] Detectado archivo: ASIGNACION_TANGIBLES_RV_20250808.csv
2025-08-08 11:03:47 [INFO] Orden de columnas calculadas: ['FECHA_PDV', 'Periodo']
2025-08-08 11:03:48 [INFO] 14030 registros insertados en tabla 'alarma_asignacion_tangibles' desde archivo: ASIGNACION_TANGIBLES_RV_20250808.csv
2025-08-08 11:03:48 [INFO] Procedimiento ejecutado: sp_update_resumen_simcard2 con parámetro: N/A
2025-08-08 11:03:48 [INFO] Archivo procesado correctamente: ASIGNACION_TANGIBLES_RV_20250808.csv
2025-08-08 11:06:03 [INFO] Iniciando monitor de archivos...
2025-08-08 11:06:18 [INFO] Detectado archivo: ASIGNACION_TANGIBLES_RV_20250808.csv
2025-08-08 11:06:18 [INFO] Orden de columnas calculadas: ['FECHA_PDV', 'Periodo']
2025-08-08 11:15:16 [INFO] Iniciando monitor de archivos...
2025-08-08 11:15:16 [INFO] Detectado archivo: ASIGNACION_TANGIBLES_RV_20250808.csv
2025-08-08 11:15:16 [INFO] Orden de columnas calculadas: ['FECHA_PDV', 'Periodo']
2025-08-08 11:16:22 [INFO] Iniciando monitor de archivos...
2025-08-08 11:16:22 [INFO] Detectado archivo: ASIGNACION_TANGIBLES_RV_20250808.csv
2025-08-08 11:16:22 [INFO] Orden de columnas calculadas: ['FECHA_PDV', 'Periodo']
2025-08-08 11:16:53 [INFO] Iniciando monitor de archivos...
2025-08-08 11:16:53 [INFO] Detectado archivo: ASIGNACION_TANGIBLES_RV_20250808.csv
2025-08-08 11:16:53 [INFO] Orden de columnas calculadas: ['FECHA_PDV', 'Periodo']
2025-08-08 11:17:48 [INFO] Iniciando monitor de archivos...
2025-08-08 11:17:48 [INFO] Detectado archivo: ASIGNACION_TANGIBLES_RV_20250808.csv
2025-08-08 11:17:48 [INFO] Orden de columnas calculadas: ['FECHA_PDV', 'Periodo']
2025-08-08 11:19:37 [INFO] Iniciando monitor de archivos...
2025-08-08 11:19:37 [INFO] Detectado archivo: ASIGNACION_TANGIBLES_RV_20250808.csv
2025-08-08 11:19:37 [INFO] Orden de columnas calculadas: ['FECHA_PDV', 'Periodo']
2025-08-08 11:27:02 [INFO] Iniciando monitor de archivos...
2025-08-08 11:27:02 [INFO] Detectado archivo: ASIGNACION_TANGIBLES_RV_20250808.csv
2025-08-08 11:27:02 [INFO] Orden de columnas calculadas: ['FECHA_PDV', 'Periodo']
2025-08-08 11:27:53 [INFO] Iniciando monitor de archivos...
2025-08-08 11:27:53 [INFO] Detectado archivo: ASIGNACION_TANGIBLES_RV_20250808.csv
2025-08-08 11:27:53 [INFO] Orden de columnas calculadas: ['FECHA_PDV', 'Periodo']
2025-08-08 11:28:57 [INFO] Iniciando monitor de archivos...
2025-08-08 11:28:57 [INFO] Detectado archivo: ASIGNACION_TANGIBLES_RV_20250808.csv
2025-08-08 11:28:57 [INFO] Orden de columnas calculadas: ['FECHA_PDV', 'Periodo']
2025-08-08 11:29:01 [INFO] 14030 registros insertados en tabla 'alarma_asignacion_tangibles' desde archivo: ASIGNACION_TANGIBLES_RV_20250808.csv
2025-08-08 11:29:01 [INFO] Procedimiento ejecutado: sp_update_resumen_simcard2 con parámetro: N/A
2025-08-08 11:29:01 [INFO] Archivo procesado correctamente: ASIGNACION_TANGIBLES_RV_20250808.csv
2025-08-08 11:30:45 [INFO] Iniciando monitor de archivos...
2025-08-08 11:30:50 [INFO] Detectado archivo: ASIGNACION_TANGIBLES_RV_20250808.csv
2025-08-08 11:30:50 [INFO] Orden de columnas calculadas: ['FECHA_PDV', 'Periodo']
2025-08-08 11:30:52 [INFO] 14030 registros insertados en tabla 'alarma_asignacion_tangibles' desde archivo: ASIGNACION_TANGIBLES_RV_20250808.csv
2025-08-08 11:30:52 [INFO] Procedimiento ejecutado: sp_update_resumen_simcard2 con parámetro: N/A
2025-08-08 11:30:52 [INFO] Archivo procesado correctamente: ASIGNACION_TANGIBLES_RV_20250808.csv
2025-08-08 11:35:16 [INFO] Iniciando monitor de archivos...
2025-08-08 11:35:21 [INFO] Detectado archivo: ASIGNACION_TANGIBLES_RV_20250808.csv
2025-08-08 11:35:21 [INFO] Orden de columnas calculadas: ['FECHA_PDV', 'Periodo']
2025-08-08 11:35:23 [INFO] 14030 registros insertados en tabla 'alarma_asignacion_tangibles' desde archivo: ASIGNACION_TANGIBLES_RV_20250808.csv
2025-08-08 11:35:23 [INFO] Procedimiento ejecutado: sp_update_resumen_simcard2 con parámetro: N/A
2025-08-08 11:35:23 [INFO] Archivo procesado correctamente: ASIGNACION_TANGIBLES_RV_20250808.csv
2025-08-08 11:37:53 [INFO] Detectado archivo: ASIGNACION_TANGIBLES_RV_20250807.csv
2025-08-08 11:37:53 [INFO] Orden de columnas calculadas: ['FECHA_PDV', 'Periodo']
2025-08-08 11:37:54 [INFO] 11583 registros insertados en tabla 'alarma_asignacion_tangibles' desde archivo: ASIGNACION_TANGIBLES_RV_20250807.csv
2025-08-08 11:37:54 [INFO] Procedimiento ejecutado: sp_update_resumen_simcard2 con parámetro: N/A
2025-08-08 11:37:54 [INFO] Archivo procesado correctamente: ASIGNACION_TANGIBLES_RV_20250807.csv
2025-08-08 11:40:09 [INFO] Iniciando monitor de archivos...
2025-08-08 11:40:29 [INFO] Detectado archivo: ASIGNACION_TANGIBLES_RV_20250807.csv
2025-08-08 11:40:29 [INFO] Orden de columnas calculadas: ['FECHA_PDV', 'Periodo']
2025-08-08 11:40:30 [INFO] 11583 registros insertados en tabla 'alarma_asignacion_tangibles' desde archivo: ASIGNACION_TANGIBLES_RV_20250807.csv
2025-08-08 11:40:30 [INFO] Procedimiento ejecutado: sp_update_resumen_simcard2 con parámetro: N/A
2025-08-08 11:40:30 [INFO] Archivo procesado correctamente: ASIGNACION_TANGIBLES_RV_20250807.csv
2025-08-08 11:41:00 [INFO] Detectado archivo: ASIGNACION_TANGIBLES_RV_20250808.csv
2025-08-08 11:41:00 [INFO] Orden de columnas calculadas: ['FECHA_PDV', 'Periodo']
2025-08-08 11:41:01 [INFO] 14030 registros insertados en tabla 'alarma_asignacion_tangibles' desde archivo: ASIGNACION_TANGIBLES_RV_20250808.csv
2025-08-08 11:41:01 [INFO] Procedimiento ejecutado: sp_update_resumen_simcard2 con parámetro: N/A
2025-08-08 11:41:01 [INFO] Archivo procesado correctamente: ASIGNACION_TANGIBLES_RV_20250808.csv
2025-08-08 13:58:44 [INFO] Iniciando monitor de archivos...
2025-08-08 14:00:04 [INFO] Detectado archivo: KPI_DEALER_RV_20250808.csv
2025-08-08 14:00:04 [INFO] 145 registros insertados en tabla 'kpisdealer' desde archivo: KPI_DEALER_RV_20250808.csv
2025-08-08 14:00:04 [INFO] Archivo procesado correctamente: KPI_DEALER_RV_20250808.csv
2025-08-08 14:18:23 [INFO] Iniciando monitor de archivos...
2025-08-08 14:18:53 [INFO] Detectado archivo: TMY_CASHIN_BPAYMT_20250807.csv
2025-08-08 14:18:53 [INFO] Borrando de 'cashin' donde cashinParticion = 202508
2025-08-08 14:18:53 [ERROR] 1054 (42S22): Unknown column 'cashinIdDealer' in 'field list'
Traceback (most recent call last):
  File "C:\Users\wilme\AppData\Local\Programs\Python\Python313\Lib\site-packages\mysql\connector\connection_cext.py", line 706, in cmd_query
    self._cmysql.query(
    ~~~~~~~~~~~~~~~~~~^
        query,
        ^^^^^^
    ...<3 lines>...
        query_attrs=self.query_attrs,
        ^^^^^^^^^^^^^^^^^^^^^^^^^^^^^
    )
    ^
_mysql_connector.MySQLInterfaceError: Unknown column 'cashinIdDealer' in 'field list'

The above exception was the direct cause of the following exception:

Traceback (most recent call last):
  File "C:\workspace\rv\projects\AutoUploader\db.py", line 33, in insert_into_table
    cursor.executemany(sql, batch)
    ~~~~~~~~~~~~~~~~~~^^^^^^^^^^^^
  File "C:\Users\wilme\AppData\Local\Programs\Python\Python313\Lib\site-packages\mysql\connector\cursor_cext.py", line 481, in executemany
    return self.execute(stmt)
           ~~~~~~~~~~~~^^^^^^
  File "C:\Users\wilme\AppData\Local\Programs\Python\Python313\Lib\site-packages\mysql\connector\cursor_cext.py", line 357, in execute
    result = self._connection.cmd_query(
        stmt,
    ...<2 lines>...
        raw_as_string=self._raw_as_string,
    )
  File "C:\Users\wilme\AppData\Local\Programs\Python\Python313\Lib\site-packages\mysql\connector\opentelemetry\context_propagation.py", line 97, in wrapper
    return method(cnx, *args, **kwargs)
  File "C:\Users\wilme\AppData\Local\Programs\Python\Python313\Lib\site-packages\mysql\connector\connection_cext.py", line 714, in cmd_query
    raise get_mysql_exception(
        err.errno, msg=err.msg, sqlstate=err.sqlstate
    ) from err
mysql.connector.errors.ProgrammingError: 1054 (42S22): Unknown column 'cashinIdDealer' in 'field list'
2025-08-08 14:18:53 [ERROR] Error procesando archivo TMY_CASHIN_BPAYMT_20250807.csv: 1054 (42S22): Unknown column 'cashinIdDealer' in 'field list'
2025-08-08 14:18:53 [ERROR] 1054 (42S22): Unknown column 'cashinIdDealer' in 'field list'
Traceback (most recent call last):
  File "C:\Users\wilme\AppData\Local\Programs\Python\Python313\Lib\site-packages\mysql\connector\connection_cext.py", line 706, in cmd_query
    self._cmysql.query(
    ~~~~~~~~~~~~~~~~~~^
        query,
        ^^^^^^
    ...<3 lines>...
        query_attrs=self.query_attrs,
        ^^^^^^^^^^^^^^^^^^^^^^^^^^^^^
    )
    ^
_mysql_connector.MySQLInterfaceError: Unknown column 'cashinIdDealer' in 'field list'

The above exception was the direct cause of the following exception:

Traceback (most recent call last):
  File "C:\workspace\rv\projects\AutoUploader\processor.py", line 137, in procesar_archivo
    insert_into_table(tabla, columnas_finales, filas_finales, batch_size=MAX_BATCH_SIZE, insert_type=tipo_insercion)
    ~~~~~~~~~~~~~~~~~^^^^^^^^^^^^^^^^^^^^^^^^^^^^^^^^^^^^^^^^^^^^^^^^^^^^^^^^^^^^^^^^^^^^^^^^^^^^^^^^^^^^^^^^^^^^^^^
  File "C:\workspace\rv\projects\AutoUploader\db.py", line 38, in insert_into_table
    raise e
  File "C:\workspace\rv\projects\AutoUploader\db.py", line 33, in insert_into_table
    cursor.executemany(sql, batch)
    ~~~~~~~~~~~~~~~~~~^^^^^^^^^^^^
  File "C:\Users\wilme\AppData\Local\Programs\Python\Python313\Lib\site-packages\mysql\connector\cursor_cext.py", line 481, in executemany
    return self.execute(stmt)
           ~~~~~~~~~~~~^^^^^^
  File "C:\Users\wilme\AppData\Local\Programs\Python\Python313\Lib\site-packages\mysql\connector\cursor_cext.py", line 357, in execute
    result = self._connection.cmd_query(
        stmt,
    ...<2 lines>...
        raw_as_string=self._raw_as_string,
    )
  File "C:\Users\wilme\AppData\Local\Programs\Python\Python313\Lib\site-packages\mysql\connector\opentelemetry\context_propagation.py", line 97, in wrapper
    return method(cnx, *args, **kwargs)
  File "C:\Users\wilme\AppData\Local\Programs\Python\Python313\Lib\site-packages\mysql\connector\connection_cext.py", line 714, in cmd_query
    raise get_mysql_exception(
        err.errno, msg=err.msg, sqlstate=err.sqlstate
    ) from err
mysql.connector.errors.ProgrammingError: 1054 (42S22): Unknown column 'cashinIdDealer' in 'field list'
2025-08-08 14:18:53 [ERROR] Archivo movido a carpeta de errores: TMY_CASHIN_BPAYMT_20250807.csv
2025-08-08 14:20:24 [INFO] Iniciando monitor de archivos...
2025-08-08 14:20:34 [INFO] Detectado archivo: TMY_CASHIN_BPAYMT_20250807.csv
2025-08-08 14:20:34 [INFO] Borrando de 'cashin' donde cashinParticion = 202508
2025-08-08 14:20:35 [ERROR] 1054 (42S22): Unknown column 'cashinNombreDealer' in 'field list'
Traceback (most recent call last):
  File "C:\Users\wilme\AppData\Local\Programs\Python\Python313\Lib\site-packages\mysql\connector\connection_cext.py", line 706, in cmd_query
    self._cmysql.query(
    ~~~~~~~~~~~~~~~~~~^
        query,
        ^^^^^^
    ...<3 lines>...
        query_attrs=self.query_attrs,
        ^^^^^^^^^^^^^^^^^^^^^^^^^^^^^
    )
    ^
_mysql_connector.MySQLInterfaceError: Unknown column 'cashinNombreDealer' in 'field list'

The above exception was the direct cause of the following exception:

Traceback (most recent call last):
  File "C:\workspace\rv\projects\AutoUploader\db.py", line 33, in insert_into_table
    cursor.executemany(sql, batch)
    ~~~~~~~~~~~~~~~~~~^^^^^^^^^^^^
  File "C:\Users\wilme\AppData\Local\Programs\Python\Python313\Lib\site-packages\mysql\connector\cursor_cext.py", line 481, in executemany
    return self.execute(stmt)
           ~~~~~~~~~~~~^^^^^^
  File "C:\Users\wilme\AppData\Local\Programs\Python\Python313\Lib\site-packages\mysql\connector\cursor_cext.py", line 357, in execute
    result = self._connection.cmd_query(
        stmt,
    ...<2 lines>...
        raw_as_string=self._raw_as_string,
    )
  File "C:\Users\wilme\AppData\Local\Programs\Python\Python313\Lib\site-packages\mysql\connector\opentelemetry\context_propagation.py", line 97, in wrapper
    return method(cnx, *args, **kwargs)
  File "C:\Users\wilme\AppData\Local\Programs\Python\Python313\Lib\site-packages\mysql\connector\connection_cext.py", line 714, in cmd_query
    raise get_mysql_exception(
        err.errno, msg=err.msg, sqlstate=err.sqlstate
    ) from err
mysql.connector.errors.ProgrammingError: 1054 (42S22): Unknown column 'cashinNombreDealer' in 'field list'
2025-08-08 14:20:35 [ERROR] Error procesando archivo TMY_CASHIN_BPAYMT_20250807.csv: 1054 (42S22): Unknown column 'cashinNombreDealer' in 'field list'
2025-08-08 14:20:35 [ERROR] 1054 (42S22): Unknown column 'cashinNombreDealer' in 'field list'
Traceback (most recent call last):
  File "C:\Users\wilme\AppData\Local\Programs\Python\Python313\Lib\site-packages\mysql\connector\connection_cext.py", line 706, in cmd_query
    self._cmysql.query(
    ~~~~~~~~~~~~~~~~~~^
        query,
        ^^^^^^
    ...<3 lines>...
        query_attrs=self.query_attrs,
        ^^^^^^^^^^^^^^^^^^^^^^^^^^^^^
    )
    ^
_mysql_connector.MySQLInterfaceError: Unknown column 'cashinNombreDealer' in 'field list'

The above exception was the direct cause of the following exception:

Traceback (most recent call last):
  File "C:\workspace\rv\projects\AutoUploader\processor.py", line 137, in procesar_archivo
    insert_into_table(tabla, columnas_finales, filas_finales, batch_size=MAX_BATCH_SIZE, insert_type=tipo_insercion)
    ~~~~~~~~~~~~~~~~~^^^^^^^^^^^^^^^^^^^^^^^^^^^^^^^^^^^^^^^^^^^^^^^^^^^^^^^^^^^^^^^^^^^^^^^^^^^^^^^^^^^^^^^^^^^^^^^
  File "C:\workspace\rv\projects\AutoUploader\db.py", line 38, in insert_into_table
    raise e
  File "C:\workspace\rv\projects\AutoUploader\db.py", line 33, in insert_into_table
    cursor.executemany(sql, batch)
    ~~~~~~~~~~~~~~~~~~^^^^^^^^^^^^
  File "C:\Users\wilme\AppData\Local\Programs\Python\Python313\Lib\site-packages\mysql\connector\cursor_cext.py", line 481, in executemany
    return self.execute(stmt)
           ~~~~~~~~~~~~^^^^^^
  File "C:\Users\wilme\AppData\Local\Programs\Python\Python313\Lib\site-packages\mysql\connector\cursor_cext.py", line 357, in execute
    result = self._connection.cmd_query(
        stmt,
    ...<2 lines>...
        raw_as_string=self._raw_as_string,
    )
  File "C:\Users\wilme\AppData\Local\Programs\Python\Python313\Lib\site-packages\mysql\connector\opentelemetry\context_propagation.py", line 97, in wrapper
    return method(cnx, *args, **kwargs)
  File "C:\Users\wilme\AppData\Local\Programs\Python\Python313\Lib\site-packages\mysql\connector\connection_cext.py", line 714, in cmd_query
    raise get_mysql_exception(
        err.errno, msg=err.msg, sqlstate=err.sqlstate
    ) from err
mysql.connector.errors.ProgrammingError: 1054 (42S22): Unknown column 'cashinNombreDealer' in 'field list'
2025-08-08 14:20:35 [ERROR] Archivo movido a carpeta de errores: TMY_CASHIN_BPAYMT_20250807.csv
2025-08-08 14:21:00 [INFO] Detectado archivo: TMY_CASHIN_BPAYMT_20250807.csv
2025-08-08 14:21:00 [INFO] Borrando de 'cashin' donde cashinParticion = 202508
2025-08-08 14:21:00 [ERROR] 1054 (42S22): Unknown column 'cashinNombreDealer' in 'field list'
Traceback (most recent call last):
  File "C:\Users\wilme\AppData\Local\Programs\Python\Python313\Lib\site-packages\mysql\connector\connection_cext.py", line 706, in cmd_query
    self._cmysql.query(
    ~~~~~~~~~~~~~~~~~~^
        query,
        ^^^^^^
    ...<3 lines>...
        query_attrs=self.query_attrs,
        ^^^^^^^^^^^^^^^^^^^^^^^^^^^^^
    )
    ^
_mysql_connector.MySQLInterfaceError: Unknown column 'cashinNombreDealer' in 'field list'

The above exception was the direct cause of the following exception:

Traceback (most recent call last):
  File "C:\workspace\rv\projects\AutoUploader\db.py", line 33, in insert_into_table
    cursor.executemany(sql, batch)
    ~~~~~~~~~~~~~~~~~~^^^^^^^^^^^^
  File "C:\Users\wilme\AppData\Local\Programs\Python\Python313\Lib\site-packages\mysql\connector\cursor_cext.py", line 481, in executemany
    return self.execute(stmt)
           ~~~~~~~~~~~~^^^^^^
  File "C:\Users\wilme\AppData\Local\Programs\Python\Python313\Lib\site-packages\mysql\connector\cursor_cext.py", line 357, in execute
    result = self._connection.cmd_query(
        stmt,
    ...<2 lines>...
        raw_as_string=self._raw_as_string,
    )
  File "C:\Users\wilme\AppData\Local\Programs\Python\Python313\Lib\site-packages\mysql\connector\opentelemetry\context_propagation.py", line 97, in wrapper
    return method(cnx, *args, **kwargs)
  File "C:\Users\wilme\AppData\Local\Programs\Python\Python313\Lib\site-packages\mysql\connector\connection_cext.py", line 714, in cmd_query
    raise get_mysql_exception(
        err.errno, msg=err.msg, sqlstate=err.sqlstate
    ) from err
mysql.connector.errors.ProgrammingError: 1054 (42S22): Unknown column 'cashinNombreDealer' in 'field list'
2025-08-08 14:21:00 [ERROR] Error procesando archivo TMY_CASHIN_BPAYMT_20250807.csv: 1054 (42S22): Unknown column 'cashinNombreDealer' in 'field list'
2025-08-08 14:21:00 [ERROR] 1054 (42S22): Unknown column 'cashinNombreDealer' in 'field list'
Traceback (most recent call last):
  File "C:\Users\wilme\AppData\Local\Programs\Python\Python313\Lib\site-packages\mysql\connector\connection_cext.py", line 706, in cmd_query
    self._cmysql.query(
    ~~~~~~~~~~~~~~~~~~^
        query,
        ^^^^^^
    ...<3 lines>...
        query_attrs=self.query_attrs,
        ^^^^^^^^^^^^^^^^^^^^^^^^^^^^^
    )
    ^
_mysql_connector.MySQLInterfaceError: Unknown column 'cashinNombreDealer' in 'field list'

The above exception was the direct cause of the following exception:

Traceback (most recent call last):
  File "C:\workspace\rv\projects\AutoUploader\processor.py", line 137, in procesar_archivo
    insert_into_table(tabla, columnas_finales, filas_finales, batch_size=MAX_BATCH_SIZE, insert_type=tipo_insercion)
    ~~~~~~~~~~~~~~~~~^^^^^^^^^^^^^^^^^^^^^^^^^^^^^^^^^^^^^^^^^^^^^^^^^^^^^^^^^^^^^^^^^^^^^^^^^^^^^^^^^^^^^^^^^^^^^^^
  File "C:\workspace\rv\projects\AutoUploader\db.py", line 38, in insert_into_table
    raise e
  File "C:\workspace\rv\projects\AutoUploader\db.py", line 33, in insert_into_table
    cursor.executemany(sql, batch)
    ~~~~~~~~~~~~~~~~~~^^^^^^^^^^^^
  File "C:\Users\wilme\AppData\Local\Programs\Python\Python313\Lib\site-packages\mysql\connector\cursor_cext.py", line 481, in executemany
    return self.execute(stmt)
           ~~~~~~~~~~~~^^^^^^
  File "C:\Users\wilme\AppData\Local\Programs\Python\Python313\Lib\site-packages\mysql\connector\cursor_cext.py", line 357, in execute
    result = self._connection.cmd_query(
        stmt,
    ...<2 lines>...
        raw_as_string=self._raw_as_string,
    )
  File "C:\Users\wilme\AppData\Local\Programs\Python\Python313\Lib\site-packages\mysql\connector\opentelemetry\context_propagation.py", line 97, in wrapper
    return method(cnx, *args, **kwargs)
  File "C:\Users\wilme\AppData\Local\Programs\Python\Python313\Lib\site-packages\mysql\connector\connection_cext.py", line 714, in cmd_query
    raise get_mysql_exception(
        err.errno, msg=err.msg, sqlstate=err.sqlstate
    ) from err
mysql.connector.errors.ProgrammingError: 1054 (42S22): Unknown column 'cashinNombreDealer' in 'field list'
2025-08-08 14:21:00 [ERROR] Archivo movido a carpeta de errores: TMY_CASHIN_BPAYMT_20250807.csv
2025-08-08 14:21:08 [INFO] Iniciando monitor de archivos...
2025-08-08 14:21:13 [INFO] Detectado archivo: TMY_CASHIN_BPAYMT_20250807.csv
2025-08-08 14:21:13 [INFO] Borrando de 'cashin' donde cashinParticion = 202508
2025-08-08 14:21:14 [INFO] 12814 registros insertados en tabla 'cashin' desde archivo: TMY_CASHIN_BPAYMT_20250807.csv
2025-08-08 14:21:14 [ERROR] Error ejecutando procedimiento Insert_Resumen_tmy: 1366 (HY000): Incorrect decimal value: '' for column 'tmyCashinMesAnt' at row 1
2025-08-08 14:21:14 [ERROR] Error procesando archivo TMY_CASHIN_BPAYMT_20250807.csv: 1366 (HY000): Incorrect decimal value: '' for column 'tmyCashinMesAnt' at row 1
2025-08-08 14:21:14 [ERROR] 1366 (HY000): Incorrect decimal value: '' for column 'tmyCashinMesAnt' at row 1
Traceback (most recent call last):
  File "C:\Users\wilme\AppData\Local\Programs\Python\Python313\Lib\site-packages\mysql\connector\connection_cext.py", line 706, in cmd_query
    self._cmysql.query(
    ~~~~~~~~~~~~~~~~~~^
        query,
        ^^^^^^
    ...<3 lines>...
        query_attrs=self.query_attrs,
        ^^^^^^^^^^^^^^^^^^^^^^^^^^^^^
    )
    ^
_mysql_connector.MySQLInterfaceError: Incorrect decimal value: '' for column 'tmyCashinMesAnt' at row 1

The above exception was the direct cause of the following exception:

Traceback (most recent call last):
  File "C:\workspace\rv\projects\AutoUploader\processor.py", line 153, in procesar_archivo
    raise e
  File "C:\workspace\rv\projects\AutoUploader\processor.py", line 146, in procesar_archivo
    execute_stored_procedure(nombre, args=(fecha_yyyymm,))
    ~~~~~~~~~~~~~~~~~~~~~~~~^^^^^^^^^^^^^^^^^^^^^^^^^^^^^^
  File "C:\workspace\rv\projects\AutoUploader\db.py", line 48, in execute_stored_procedure
    cursor.callproc(procedure_name, args)
    ~~~~~~~~~~~~~~~^^^^^^^^^^^^^^^^^^^^^^
  File "C:\Users\wilme\AppData\Local\Programs\Python\Python313\Lib\site-packages\mysql\connector\cursor_cext.py", line 566, in callproc
    result = self._connection.cmd_query(
        call, raw=self._raw, raw_as_string=self._raw_as_string
    )
  File "C:\Users\wilme\AppData\Local\Programs\Python\Python313\Lib\site-packages\mysql\connector\opentelemetry\context_propagation.py", line 97, in wrapper
    return method(cnx, *args, **kwargs)
  File "C:\Users\wilme\AppData\Local\Programs\Python\Python313\Lib\site-packages\mysql\connector\connection_cext.py", line 714, in cmd_query
    raise get_mysql_exception(
        err.errno, msg=err.msg, sqlstate=err.sqlstate
    ) from err
mysql.connector.errors.DatabaseError: 1366 (HY000): Incorrect decimal value: '' for column 'tmyCashinMesAnt' at row 1
2025-08-08 14:21:14 [ERROR] Archivo movido a carpeta de errores: TMY_CASHIN_BPAYMT_20250807.csv
2025-08-08 14:22:54 [INFO] Detectado archivo: GROSS_TMY_20250808.csv
2025-08-08 14:22:54 [INFO] 411 registros insertados en tabla 'alarma_gross_tmy' desde archivo: GROSS_TMY_20250808.csv
2025-08-08 14:22:54 [INFO] Procedimiento ejecutado: sp_update_resumen_simcard2 con parámetro: N/A
2025-08-08 14:22:54 [INFO] Archivo procesado correctamente: GROSS_TMY_20250808.csv
2025-08-08 14:37:15 [INFO] Iniciando monitor de archivos...
2025-08-08 14:37:45 [INFO] Detectado archivo: PDA_SMART_20250808.csv
2025-08-08 14:37:46 [INFO] Borrando de 'pdasmart' donde Periodo = 202508
2025-08-08 14:37:46 [INFO] 99 registros insertados en tabla 'pdasmart' desde archivo: PDA_SMART_20250808.csv
2025-08-08 14:37:46 [INFO] Archivo procesado correctamente: PDA_SMART_20250808.csv
2025-08-08 15:34:38 [INFO] Iniciando monitor de archivos...
2025-08-08 15:34:53 [INFO] Detectado archivo: GROSS_PREPAGO_20250808.csv
2025-08-08 15:34:53 [INFO] Borrando de 'grossprepago' donde grossPrepagoAnomesActivacion = 202508
2025-08-08 15:34:55 [INFO] 10611 registros insertados en tabla 'grossprepago' desde archivo: GROSS_PREPAGO_20250808.csv
2025-08-08 15:34:55 [INFO] Archivo procesado correctamente: GROSS_PREPAGO_20250808.csv
2025-08-08 15:57:59 [INFO] Iniciando monitor de archivos...
2025-08-08 15:58:24 [INFO] Detectado archivo: GROSS_PREPAGO_20250808.csv
2025-08-08 15:58:25 [INFO] Borrando de 'grossprepago' donde grossPrepagoAnomesActivacion = 202508
2025-08-08 15:58:36 [INFO] 10611 registros insertados en tabla 'grossprepago' desde archivo: GROSS_PREPAGO_20250808.csv
2025-08-08 16:05:54 [INFO] Procedimiento ejecutado: Insert_Resumen_Gross con parámetro: 202508
2025-08-08 16:16:27 [INFO] Procedimiento ejecutado: Insert_Resumen_Gross_Sucursal con parámetro: 202508
2025-08-08 16:16:29 [INFO] Procedimiento ejecutado: Insert_Resumen_Gross_Departamento con parámetro: 202508
2025-08-08 16:16:33 [INFO] Procedimiento ejecutado: Insert_Resumen_Gross_Vendedor con parámetro: 202508
2025-08-08 16:16:34 [INFO] Procedimiento ejecutado: Insert_Resumen_Gross_Diario con parámetro: 202508
2025-08-08 16:16:34 [ERROR] Error procesando archivo GROSS_PREPAGO_20250808.csv: [WinError 183] No se puede crear un archivo que ya existe: 'C:\\Users\\wilme\\Desktop\\FTP\\GROSS_PREPAGO_20250808.csv' -> 'C:\\Users\\wilme\\Documents\\procesados\\GROSS_PREPAGO_20250808.csv'
2025-08-08 16:16:34 [ERROR] [WinError 183] No se puede crear un archivo que ya existe: 'C:\\Users\\wilme\\Desktop\\FTP\\GROSS_PREPAGO_20250808.csv' -> 'C:\\Users\\wilme\\Documents\\procesados\\GROSS_PREPAGO_20250808.csv'
Traceback (most recent call last):
  File "C:\workspace\rv\projects\AutoUploader\processor.py", line 156, in procesar_archivo
    os.rename(ruta_archivo, os.path.join(PROCESSED_FOLDER, archivo))
    ~~~~~~~~~^^^^^^^^^^^^^^^^^^^^^^^^^^^^^^^^^^^^^^^^^^^^^^^^^^^^^^^
FileExistsError: [WinError 183] No se puede crear un archivo que ya existe: 'C:\\Users\\wilme\\Desktop\\FTP\\GROSS_PREPAGO_20250808.csv' -> 'C:\\Users\\wilme\\Documents\\procesados\\GROSS_PREPAGO_20250808.csv'
2025-08-08 16:16:34 [ERROR] Archivo movido a carpeta de errores: GROSS_PREPAGO_20250808.csv
2025-08-08 16:16:39 [INFO] Detectado archivo: TMY_CASHIN_BPAYMT_20250731.csv
2025-08-08 16:16:40 [INFO] Borrando de 'cashin' donde cashinParticion = 202507
2025-08-08 16:17:02 [INFO] 66688 registros insertados en tabla 'cashin' desde archivo: TMY_CASHIN_BPAYMT_20250731.csv
2025-08-08 16:35:27 [INFO] Procedimiento ejecutado: Insert_Resumen_tmy con parámetro: 202507
2025-08-08 16:35:31 [INFO] Procedimiento ejecutado: UpdateMicroTigoMoney con parámetro: 202507
2025-08-08 16:35:31 [INFO] Archivo procesado correctamente: TMY_CASHIN_BPAYMT_20250731.csv
2025-08-08 17:12:59 [INFO] Iniciando monitor de archivos...
2025-08-08 17:13:34 [INFO] Detectado archivo: ASIGNACION_TANGIBLES_RV_20250808.csv
2025-08-08 17:13:35 [INFO] 14030 registros insertados en tabla 'alarma_asignacion_tangibles' desde archivo: ASIGNACION_TANGIBLES_RV_20250808.csv
2025-08-08 17:13:35 [INFO] Archivo procesado correctamente: ASIGNACION_TANGIBLES_RV_20250808.csv
2025-08-08 17:23:28 [INFO] Iniciando monitor de archivos...
2025-08-08 17:23:48 [INFO] Detectado archivo: SELL_IN_20250731.csv
2025-08-08 17:23:50 [ERROR] Archivo movido a carpeta de errores: SELL_IN_20250731.csv
2025-08-08 17:27:01 [INFO] Iniciando monitor de archivos...
2025-08-08 17:27:26 [INFO] Detectado archivo: SELL_IN_20250731.csv
2025-08-08 17:27:28 [INFO] Borrando de 'sellin' donde Periodo = 202507
2025-08-08 17:28:01 [INFO] 171214 registros insertados en tabla 'sellin' desde archivo: SELL_IN_20250731.csv
2025-08-08 17:29:21 [INFO] Archivo procesado correctamente: SELL_IN_20250731.csv
